Workbook

Sheet Resumen
A1: Resumen — niveles y costo de GPIO Génesis × LIIE1214 (solo los 3 bloques de la página)
A2: MVP = 5 niveles de GPIO · 3 bloques = GPIO, Tiempo y serie, Analógico y buses (22 niveles). El detalle por parte y por tipo de trabajo está en la hoja Desglose.
A4: Concepto | B4: MVP | C4: 3 bloques
A5: Niveles | B5: =COUNTIFS(Niveles!$H$5:$H$26,"<=1") -> 5 | C5: =COUNTIFS(Niveles!$H$5:$H$26,"<=2") -> 22
A6: Horas totales | B6: =Desglose!B11 -> 423 | C6: =Desglose!C11 -> 972
A7: de programación | B7: =Desglose!B6 -> 214.6 | C7: =Desglose!C6 -> 481.4
A8: de diseño gráfico | B8: =Desglose!B7 -> 98 | C8: =Desglose!C7 -> 164
A9: de sonido | B9: =Desglose!B8 -> 18 | C9: =Desglose!C8 -> 35
A10: de diseño de niveles y contenido | B10: =Desglose!B9 -> 48.4 | C10: =Desglose!C9 -> 151.6
A11: de pruebas y gestión | B11: =Desglose!B10 -> 44 | C11: =Desglose!C10 -> 140
A12: Semanas necesarias (personas × h/semana) | B12: =B6/(Supuestos!$B$9*Supuestos!$B$10) -> 17.625 | C12: =C6/(Supuestos!$B$9*Supuestos!$B$10) -> 40.5
A13: Semanas de más contra las disponibles | B13: =B12-Supuestos!$B$11 -> 11.625 | C13: =C12-Supuestos!$B$11 -> 34.5
A15: COSTO (MXN)
A16: Desarrollo contando horas, con indirectos y contingencia | B16: =Desglose!D23 -> 50596.556 | C16: =Desglose!E23 -> 116281.16
A17: Lanzamiento, 12 meses (Steam, dominio, firma, Supabase Pro) | B17: =Desglose!C48 -> 8942.5 | C17: =Desglose!C48 -> 8942.5
A18: TOTAL DEL PROYECTO contando horas | B18: =B16+B17 -> 59539.056 | C18: =C16+C17 -> 125223.66
A19: Dinero real que sale (sin horas) | B19: =Desglose!B54 -> 8948.2558 | C19: =Desglose!C54 -> 8972.4561
A21: ECONOMÍA POR JUGADOR
A22: IA por jugador, modelo base (MXN) | B22: =SUMIFS(Niveles!$W$5:$W$26,Niveles!$H$5:$H$26,"<=1") -> 0.8575 | C22: =SUMIFS(Niveles!$W$5:$W$26,Niveles!$H$5:$H$26,"<=2") -> 6.2825
A23: IA por jugador, Haiku 4.5 (MXN) | B23: =SUMIFS(Niveles!$X$5:$X$26,Niveles!$H$5:$H$26,"<=1") -> 8.575 | C23: =SUMIFS(Niveles!$X$5:$X$26,Niveles!$H$5:$H$26,"<=2") -> 62.825
A24: Ingreso neto por copia (precio − comisión) | B24: =Supuestos!$B$3*(1-Supuestos!$B$4) -> 174.3 | C24: =Supuestos!$B$3*(1-Supuestos!$B$4) -> 174.3
A25: IA como % del ingreso neto (modelo base) | B25: =B22/B24 -> 0.0049196787 | C25: =C22/C24 -> 0.036044177
A26: IA como % del ingreso neto (Haiku 4.5) | B26: =B23/B24 -> 0.049196787 | C26: =C23/C24 -> 0.36044177
A27: Margen por copia tras IA (MXN) | B27: =B24-B22 -> 173.4425 | C27: =C24-C22 -> 168.0175
A29: PUNTO DE EQUILIBRIO PRELIMINAR (el formal es del Bloque 4)
A30: Copias para cubrir todo, contando horas | B30: =B18/B27 -> 343.27835 | C30: =C18/C27 -> 745.30127
A31: Copias para cubrir solo el dinero real | B31: =B19/B27 -> 51.592059 | C31: =C19/C27 -> 53.401914
A32: Precio mínimo si se venden las copias del escenario bajo (MXN) | B32: =(B18/Supuestos!$B$15+B22)/(1-Supuestos!$B$4) -> 851.78294 | C32: =(C18/Supuestos!$B$15+C22)/(1-Supuestos!$B$4) -> 1797.8844
A33: Precio mínimo si se venden las copias del escenario alto (MXN) | B33: =(B18/Supuestos!$B$16+B22)/(1-Supuestos!$B$4) -> 171.33659 | C33: =(C18/Supuestos!$B$16+C22)/(1-Supuestos!$B$4) -> 366.75687
A35: Lectura rápida
A36: 1) La página del curso solo incluye los 3 bloques (GPIO, Tiempo y serie, Analógico y buses): no se contempla PIO, DMA, multicore ni Micromouse.
A37: 2) La página es del RP2350 / Pico 2 con el Pico SDK, en C, sin Arduino. El juego de las semanas 5–6 usa la API de Arduino-ESP32 (pinMode, pin D5). Para alumnos de este curso conviene la API del Pico SDK; eso toca RI-04 y los documentos de las semanas 5 y 6.
A38: 3) Con las horas por semana del supuesto ni el MVP cabe en 6 semanas. Lo que decide es cuántas horas reales pueden dar y hasta qué fecha.
A39: 4) Lo caro es el motor y simular cada periférico; el arte de máquinas nuevas, el pulido de interfaz y el sonido ahora están contados por separado en la hoja Desglose.
A40: 5) La IA cuesta poco con Haiku 5.5; con Haiku 4.5 y todas las ayudas en la nube pesaría mucho más (ver el % del ingreso neto).

Sheet Supuestos
A1: Supuestos — GPIO Génesis × Embedded Systems I (LIIE1214), solo los 3 bloques de la página
A2: Tipo de cambio (MXN por USD) | B2: 17.5 | D2: Del proyecto (semana 5).
A3: Precio de venta por copia (MXN) | B3: 249 | D3: Provisional (semana 5). Se decide en el Bloque 4.
A4: Comisión del canal (Steam) | B4: 0.3 | D4: Del proyecto; falta verificar.
A5: Horas por máquina nueva (sprites + animación) | B5: 6 | D5: SUPUESTO: ~3 h de sprite y ~3 h de animación.
A6: Costos indirectos (% de los directos) | B6: 0.15 | D6: Rango del curso 10–20%.
A7: Reserva de contingencia | B7: 0.3 | D7: Rango del curso 25–40%.
A8: % de consultas de ayuda que van a la nube | B8: 0.5 | D8: Pistas 1–2 locales, 3–4 nube (Prompt 6 de la semana 6).
A9: Personas en el equipo | B9: 2 | D9: José Carlos y Yael.
A10: Horas por semana por persona para el proyecto | B10: 12 | D10: SUPUESTO: cámbienlo por lo que realmente pueden dar.
A11: Semanas disponibles (de la semana 7 a la 13) | B11: 6 | D11: SUPUESTO: 'hasta la semana 13' (guía de la semana 6). Confirmar.
A12: Modelo de IA base | B12: Claude Haiku 5.5 | D12: Se elige de la lista.
A13: Precio de entrada del modelo base (USD por millón) | B13: =INDEX(B22:B24,MATCH(B12,A22:A24,0)) -> 0.1
A14: Precio de salida del modelo base (USD por millón) | B14: =INDEX(C22:C24,MATCH(B12,A22:A24,0)) -> 0.5
A15: Copias para el precio de equilibrio (bajo) | B15: 100
A16: Copias para el precio de equilibrio (alto) | B16: 500
A17: Consultas de prueba por nivel durante el desarrollo | B17: 100 | D17: SUPUESTO: probar el prompt del copiloto en cada nivel.
A18: Horas de sonido por nivel (elegir y mezclar efectos) | B18: 1 | D18: SUPUESTO.
A20: Precios de la API de Claude (USD por millón de tokens) — platform.claude.com, consultados el 9-oct-2026
A21: Modelo | B21: Entrada | C21: Salida
A22: Claude Haiku 4.5 | B22: 1 | C22: 5
A23: Claude Haiku 5.5 | B23: 0.1 | C23: 0.5
A24: Claude Sonnet 5.5 | B24: 2 | C24: 10
A26: Complejidad de un nivel — horas base (programación, diseño del nivel y pruebas; el arte y el sonido se cuentan aparte)
A27: Complejidad | B27: Horas base | C27: Tokens entrada | D27: Tokens salida | E27: Consultas de ayuda | F27: % programación | G27: % diseño de nivel y contenido | H27: % pruebas | I27: Suma | J27: Qué incluye
A28: S | B28: 8 | C28: 2500 | D28: 350 | E28: 40 | F28: 0.35 | G28: 0.4 | H28: 0.25 | I28: =F28+G28+H28 -> 1 | J28: Variación de algo ya construido.
A29: M | B29: 16 | C29: 3000 | D29: 400 | E29: 60 | F29: 0.4 | G29: 0.35 | H29: 0.25 | I29: =F29+G29+H29 -> 1 | J29: Concepto nuevo.
A30: L | B30: 24 | C30: 4000 | D30: 500 | E30: 80 | F30: 0.45 | G30: 0.3 | H30: 0.25 | I30: =F30+G30+H30 -> 1 | J30: Varios conceptos o mediciones; más pistas y casos de error.
A31: XL | B31: 40 | C31: 6000 | D31: 600 | E31: 100 | F31: 0.5 | G31: 0.25 | H31: 0.25 | I31: =F31+G31+H31 -> 1 | J31: Mecánica compleja (no se usa con los 3 bloques).
A32: Todo lo amarillo es estimación de Claude. Las 300 consultas por jugador de la semana 5 equivalen a ~60 por nivel en 5 niveles.
A34: Tarifa por hora según el tipo de trabajo (MXN)
A35: Disciplina | B35: MXN por hora | C35: Nota
A36: Programación | B36: 80 | C36: Ejemplo del curso ($80/h). Costo de oportunidad: nadie se paga en efectivo.
A37: Diseño gráfico | B37: 80 | C37: Ejemplo del curso ($80/h). Costo de oportunidad: nadie se paga en efectivo.
A38: Sonido | B38: 80 | C38: Ejemplo del curso ($80/h). Costo de oportunidad: nadie se paga en efectivo.
A39: Diseño de niveles y contenido | B39: 80 | C39: Ejemplo del curso ($80/h). Costo de oportunidad: nadie se paga en efectivo.
A40: Pruebas y gestión | B40: 80 | C40: Ejemplo del curso ($80/h). Costo de oportunidad: nadie se paga en efectivo.
A42: Costos de lanzamiento (12 meses)
A43: Concepto | B43: USD | C43: Estado
A44: Cuota de Steam | B44: 100 | C44: Verificado 9-oct-2026
...

Sheet Niveles
A1: Niveles propuestos — solo los temas de los 3 bloques de la página del curso
A2: Escenario mínimo: 1 = MVP (5 niveles), 2 = los 3 bloques completos. Azul = editable. El arte de máquinas nuevas y el sonido van aparte de las horas base.
A4: # | B4: Bloque | C4: Nivel (nombre en el juego) | D4: Tema del curso | E4: Concepto / API Pico SDK | F4: Máquina o escenario en la fábrica | G4: Complejidad | H4: Escenario mínimo | I4: Máquinas nuevas | J4: Horas base | K4: Prog. h | L4: Diseño de nivel h | M4: Pruebas h | N4: Arte h | O4: Sonido h | P4: HORAS TOTALES | Q4: Costo base MXN | R4: Costo arte MXN | S4: Costo sonido MXN | T4: COSTO TOTAL MXN | U4: Consultas de ayuda | V4: USD por consulta (modelo base) | W4: IA por jugador MXN (modelo base) | X4: IA por jugador MXN (Haiku 4.5) | Y4: Pruebas de IA en desarrollo MXN
A5: 1 | B5: Bloque 1 · GPIO | C5: Arranque de línea | D5: Entorno y toolchain + Control de GPIO | E5: gpio_init, gpio_set_dir, gpio_put; compilar y cargar | F5: Motor de la banda | G5: S | H5: 1 | I5: 0 | J5: =INDEX(Supuestos!$B$28:$B$31,MATCH(G5,Supuestos!$A$28:$A$31,0)) -> 8 | K5: =J5*INDEX(Supuestos!$F$28:$F$31,MATCH(G5,Supuestos!$A$28:$A$31,0)) -> 2.8 | L5: =J5*INDEX(Supuestos!$G$28:$G$31,MATCH(G5,Supuestos!$A$28:$A$31,0)) -> 3.2 | M5: =J5*INDEX(Supuestos!$H$28:$H$31,MATCH(G5,Supuestos!$A$28:$A$31,0)) -> 2 | N5: =I5*Supuestos!$B$5 -> 0 | O5: =Supuestos!$B$18 -> 1 | P5: =J5+N5+O5 -> 9 | Q5: =K5*Supuestos!$B$36+L5*Supuestos!$B$39+M5*Supuestos!$B$40 -> 640 | R5: =N5*Supuestos!$B$37 -> 0 | S5: =O5*Supuestos!$B$38 -> 80 | T5: =Q5+R5+S5 -> 720 | U5: =INDEX(Supuestos!$E$28:$E$31,MATCH(G5,Supuestos!$A$28:$A$31,0)) -> 40 | V5: =(INDEX(Supuestos!$C$28:$C$31,MATCH(G5,Supuestos!$A$28:$A$31,0))*Supuestos!$B$13+INDEX(Supuestos!$D$28:$D$31,MATCH(G5,Supuestos!$A$28:$A$31,0))*Supuestos!$B$14)/1000000 -> 0.000425 | W5: =U5*Supuestos!$B$8*V5*Supuestos!$B$2 -> 0.14875 | X5: =U5*Supuestos!$B$8*(INDEX(Supuestos!$C$28:$C$31,MATCH(G5,Supuestos!$A$28:$A$31,0))*Supuestos!$B$22+INDEX(Supuestos!$D$28:$D$31,MATCH(G5,Supuestos!$A$28:$A$31,0))*Supuestos!$C$22)/1000000*Supuestos!$B$2 -> 1.4875 | Y5: =Supuestos!$B$17*V5*Supuestos!$B$2 -> 0.74375
A6: 2 | B6: Bloque 1 · GPIO | C6: Tres estaciones | D6: Control de GPIO | E6: Máscaras 1u<<n; sio_hw->gpio_set/clr/togl | F6: Tres luces de estación | G6: S | H6: 1 | I6: 0 | J6: =INDEX(Supuestos!$B$28:$B$31,MATCH(G6,Supuestos!$A$28:$A$31,0)) -> 8 | K6: =J6*INDEX(Supuestos!$F$28:$F$31,MATCH(G6,Supuestos!$A$28:$A$31,0)) -> 2.8 | L6: =J6*INDEX(Supuestos!$G$28:$G$31,MATCH(G6,Supuestos!$A$28:$A$31,0)) -> 3.2 | M6: =J6*INDEX(Supuestos!$H$28:$H$31,MATCH(G6,Supuestos!$A$28:$A$31,0)) -> 2 | N6: =I6*Supuestos!$B$5 -> 0 | O6: =Supuestos!$B$18 -> 1 | P6: =J6+N6+O6 -> 9 | Q6: =K6*Supuestos!$B$36+L6*Supuestos!$B$39+M6*Supuestos!$B$40 -> 640 | R6: =N6*Supuestos!$B$37 -> 0 | S6: =O6*Supuestos!$B$38 -> 80 | T6: =Q6+R6+S6 -> 720 | U6: =INDEX(Supuestos!$E$28:$E$31,MATCH(G6,Supuestos!$A$28:$A$31,0)) -> 40 | V6: =(INDEX(Supuestos!$C$28:$C$31,MATCH(G6,Supuestos!$A$28:$A$31,0))*Supuestos!$B$13+INDEX(Supuestos!$D$28:$D$31,MATCH(G6,Supuestos!$A$28:$A$31,0))*Supuestos!$B$14)/1000000 -> 0.000425 | W6: =U6*Supuestos!$B$8*V6*Supuestos!$B$2 -> 0.14875 | X6: =U6*Supuestos!$B$8*(INDEX(Supuestos!$C$28:$C$31,MATCH(G6,Supuestos!$A$28:$A$31,0))*Supuestos!$B$22+INDEX(Supuestos!$D$28:$D$31,MATCH(G6,Supuestos!$A$28:$A$31,0))*Supuestos!$C$22)/1000000*Supuestos!$B$2 -> 1.4875 | Y6: =Supuestos!$B$17*V6*Supuestos!$B$2 -> 0.74375
A7: 3 | B7: Bloque 1 · GPIO | C7: Contador de chasis | D7: Control de GPIO | E7: Contador binario de 4 bits (valor << 2) | F7: Tablero de 4 LEDs | G7: S | H7: 1 | I7: 1 | J7: =INDEX(Supuestos!$B$28:$B$31,MATCH(G7,Supuestos!$A$28:$A$31,0)) -> 8 | K7: =J7*INDEX(Supuestos!$F$28:$F$31,MATCH(G7,Supuestos!$A$28:$A$31,0)) -> 2.8 | L7: =J7*INDEX(Supuestos!$G$28:$G$31,MATCH(G7,Supuestos!$A$28:$A$31,0)) -> 3.2 | M7: =J7*INDEX(Supuestos!$H$28:$H$31,MATCH(G7,Supuestos!$A$28:$A$31,0)) -> 2 | N7: =I7*Supuestos!$B$5 -> 6 | O7: =Supuestos!$B$18 -> 1 | P7: =J7+N7+O7 -> 15 | Q7: =K7*Supuestos!$B$36+L7*Supuestos!$B$39+M7*Supuestos!$B$40 -> 640 | R7: =N7*Supuestos!$B$37 -> 480 | S7: =O7*Supuestos!$B$38 -> 80 | T7: =Q7+R7+S7 -> 1200 | U7: =INDEX(Supuestos!$E$28:$E$31,MATCH(G7,Supuestos!$A$28:$A$31,0)) -> 40 | V7: =(INDEX(Supuestos!$C$28:$C$31,MATCH(G7,Supuestos!$A$28:$A$31,0))*Supuestos!$B$13+INDEX(Supuestos!$D$28:$D$31,MATCH(G7,Supuestos!$A$28:$A$31,0))*Supuestos!$B$14)/1000000 -> 0.000425 | W7: =U7*Supuestos!$B$8*V7*Supuestos!$B$2 -> 0.14875 | X7: =U7*Supuestos!$B$8*(INDEX(Supuestos!$C$28:$C$31,MATCH(G7,Supuestos!$A$28:$A$31,0))*Supuestos!$B$22+INDEX(Supuestos!$D$28:$D$31,MATCH(G7,Supuestos!$A$28:$A$31,0))*Supuestos!$C$22)/1000000*Supuestos!$B$2 -> 1.4875 | Y7: =Supuestos!$B$17*V7*Supuestos!$B$2 -> 0.74375
A8: 4 | B8: Bloque 1 · GPIO | C8: Luces de turno | D8: Control de GPIO | E8: Patrones: luz que rebota, llenar/vaciar, fuera→dentro | F8: Marquesina de la nave | G8: S | H8: 1 | I8: 1 | J8: =INDEX(Supuestos!$B$28:$B$31,MATCH(G8,Supuestos!$A$28:$A$31,0)) -> 8 | K8: =J8*INDEX(Supuestos!$F$28:$F$31,MATCH(G8,Supuestos!$A$28:$A$31,0)) -> 2.8 | L8: =J8*INDEX(Supuestos!$G$28:$G$31,MATCH(G8,Supuestos!$A$28:$A$31,0)) -> 3.2 | M8: =J8*INDEX(Supuestos!$H$28:$H$31,MATCH(G8,Supuestos!$A$28:$A$31,0)) -> 2 | N8: =I8*Supuestos!$B$5 -> 6 | O8: =Supuestos!$B$18 -> 1 | P8: =J8+N8+O8 -> 15 | Q8: =K8*Supuestos!$B$36+L8*Supuestos!$B$39+M8*Supuestos!$B$40 -> 640 | R8: =N8*Supuestos!$B$37 -> 480 | S8: =O8*Supuestos!$B$38 -> 80 | T8: =Q8+R8+S8 -> 1200 | U8: =INDEX(Supuestos!$E$28:$E$31,MATCH(G8,Supuestos!$A$28:$A$31,0)) -> 40 | V8: =(INDEX(Supuestos!$C$28:$C$31,MATCH(G8,Supuestos!$A$28:$A$31,0))*Supuestos!$B$13+INDEX(Supuestos!$D$28:$D$31,MATCH(G8,Supuestos!$A$28:$A$31,0))*Supuestos!$B$14)/1000000 -> 0.000425 | W8: =U8*Supuestos!$B$8*V8*Supuestos!$B$2 -> 0.14875 | X8: =U8*Supuestos!$B$8*(INDEX(Supuestos!$C$28:$C$31,MATCH(G8,Supuestos!$A$28:$A$31,0))*Supuestos!$B$22+INDEX(Supuestos!$D$28:$D$31,MATCH(G8,Supuestos!$A$28:$A$31,0))*Supuestos!$C$22)/1000000*Supuestos!$B$2 -> 1.4875 | Y8: =Supuestos!$B$17*V8*Supuestos!$B$2 -> 0.74375
A9: 5 | B9: Bloque 1 · GPIO | C9: Sensor de presencia | D9: Entradas digitales | E9: gpio_get, pull-up/pull-down, lógica activa en bajo | F9: Sensor + botón | G9: M | H9: 1 | I9: 1 | J9: =INDEX(Supuestos!$B$28:$B$31,MATCH(G9,Supuestos!$A$28:$A$31,0)) -> 16 | K9: =J9*INDEX(Supuestos!$F$28:$F$31,MATCH(G9,Supuestos!$A$28:$A$31,0)) -> 6.4 | L9: =J9*INDEX(Supuestos!$G$28:$G$31,MATCH(G9,Supuestos!$A$28:$A$31,0)) -> 5.6 | M9: =J9*INDEX(Supuestos!$H$28:$H$31,MATCH(G9,Supuestos!$A$28:$A$31,0)) -> 4 | N9: =I9*Supuestos!$B$5 -> 6 | O9: =Supuestos!$B$18 -> 1 | P9: =J9+N9+O9 -> 23 | Q9: =K9*Supuestos!$B$36+L9*Supuestos!$B$39+M9*Supuestos!$B$40 -> 1280 | R9: =N9*Supuestos!$B$37 -> 480 | S9: =O9*Supuestos!$B$38 -> 80 | T9: =Q9+R9+S9 -> 1840 | U9: =INDEX(Supuestos!$E$28:$E$31,MATCH(G9,Supuestos!$A$28:$A$31,0)) -> 60 | V9: =(INDEX(Supuestos!$C$28:$C$31,MATCH(G9,Supuestos!$A$28:$A$31,0))*Supuestos!$B$13+INDEX(Supuestos!$D$28:$D$31,MATCH(G9,Supuestos!$A$28:$A$31,0))*Supuestos!$B$14)/1000000 -> 0.0005 | W9: =U9*Supuestos!$B$8*V9*Supuestos!$B$2 -> 0.2625 | X9: =U9*Supuestos!$B$8*(INDEX(Supuestos!$C$28:$C$31,MATCH(G9,Supuestos!$A$28:$A$31,0))*Supuestos!$B$22+INDEX(Supuestos!$D$28:$D$31,MATCH(G9,Supuestos!$A$28:$A$31,0))*Supuestos!$C$22)/1000000*Supuestos!$B$2 -> 2.625 | Y9: =Supuestos!$B$17*V9*Supuestos!$B$2 -> 0.875
A10: 6 | B10: Bloque 1 · GPIO | C10: Botón de paro sin rebote | D10: Entradas digitales | E10: Antirrebote: retardo fijo, ventana deslizante, máquina de estados | F10: Botón de paro | G10: M | H10: 2 | I10: 0 | J10: =INDEX(Supuestos!$B$28:$B$31,MATCH(G10,Supuestos!$A$28:$A$31,0)) -> 16 | K10: =J10*INDEX(Supuestos!$F$28:$F$31,MATCH(G10,Supuestos!$A$28:$A$31,0)) -> 6.4 | L10: =J10*INDEX(Supuestos!$G$28:$G$31,MATCH(G10,Supuestos!$A$28:$A$31,0)) -> 5.6 | M10: =J10*INDEX(Supuestos!$H$28:$H$31,MATCH(G10,Supuestos!$A$28:$A$31,0)) -> 4 | N10: =I10*Supuestos!$B$5 -> 0 | O10: =Supuestos!$B$18 -> 1 | P10: =J10+N10+O10 -> 17 | Q10: =K10*Supuestos!$B$36+L10*Supuestos!$B$39+M10*Supuestos!$B$40 -> 1280 | R10: =N10*Supuestos!$B$37 -> 0 | S10: =O10*Supuestos!$B$38 -> 80 | T10: =Q10+R10+S10 -> 1360 | U10: =INDEX(Supuestos!$E$28:$E$31,MATCH(G10,Supuestos!$A$28:$A$31,0)) -> 60 | V10: =(INDEX(Supuestos!$C$28:$C$31,MATCH(G10,Supuestos!$A$28:$A$31,0))*Supuestos!$B$13+INDEX(Supuestos!$D$28:$D$31,MATCH(G10,Supuestos!$A$28:$A$31,0))*Supuestos!$B$14)/1000000 -> 0.0005 | W10: =U10*Supuestos!$B$8*V10*Supuestos!$B$2 -> 0.2625 | X10: =U10*Supuestos!$B$8*(INDEX(Supuestos!$C$28:$C$31,MATCH(G10,Supuestos!$A$28:$A$31,0))*Supuestos!$B$22+INDEX(Supuestos!$D$28:$D$31,MATCH(G10,Supuestos!$A$28:$A$31,0))*Supuestos!$C$22)/1000000*Supuestos!$B$2 -> 2.625 | Y10: =Supuestos!$B$17*V10*Supuestos!$B$2 -> 0.875
A11: 7 | B11: Bloque 1 · GPIO | C11: Paro de emergencia | D11: Interrupciones | E11: ISR por flanco, limpiar la bandera, callback de GPIO | F11: Botón de emergencia | G11: M | H11: 2 | I11: 1 | J11: =INDEX(Supuestos!$B$28:$B$31,MATCH(G11,Supuestos!$A$28:$A$31,0)) -> 16 | K11: =J11*INDEX(Supuestos!$F$28:$F$31,MATCH(G11,Supuestos!$A$28:$A$31,0)) -> 6.4 | L11: =J11*INDEX(Supuestos!$G$28:$G$31,MATCH(G11,Supuestos!$A$28:$A$31,0)) -> 5.6 | M11: =J11*INDEX(Supuestos!$H$28:$H$31,MATCH(G11,Supuestos!$A$28:$A$31,0)) -> 4 | N11: =I11*Supuestos!$B$5 -> 6 | O11: =Supuestos!$B$18 -> 1 | P11: =J11+N11+O11 -> 23 | Q11: =K11*Supuestos!$B$36+L11*Supuestos!$B$39+M11*Supuestos!$B$40 -> 1280 | R11: =N11*Supuestos!$B$37 -> 480 | S11: =O11*Supuestos!$B$38 -> 80 | T11: =Q11+R11+S11 -> 1840 | U11: =INDEX(Supuestos!$E$28:$E$31,MATCH(G11,Supuestos!$A$28:$A$31,0)) -> 60 | V11: =(INDEX(Supuestos!$C$28:$C$31,MATCH(G11,Supuestos!$A$28:$A$31,0))*Supuestos!$B$13+INDEX(Supuestos!$D$28:$D$31,MATCH(G11,Supuestos!$A$28:$A$31,0))*Supuestos!$B$14)/1000000 -> 0.0005 | W11: =U11*Supuestos!$B$8*V11*Supuestos!$B$2 -> 0.2625 | X11: =U11*Supuestos!$B$8*(INDEX(Supuestos!$C$28:$C$31,MATCH(G11,Supuestos!$A$28:$A$31,0))*Supuestos!$B$22+INDEX(Supuestos!$D$28:$D$31,MATCH(G11,Supuestos!$A$28:$A$31,0))*Supuestos!$C$22)/1000000*Supuestos!$B$2 -> 2.625 | Y11: =Supuestos!$B$17*V11*Supuestos!$B$2 -> 0.875
A12: 8 | B12: Bloque 1 · GPIO | C12: Dos botones, un callback | D12: Interrupciones | E12: Un callback compartido, flanco vs nivel | F12: Dos botones de línea | G12: M | H12: 2 | I12: 0 | J12: =INDEX(Supuestos!$B$28:$B$31,MATCH(G12,Supuestos!$A$28:$A$31,0)) -> 16 | K12: =J12*INDEX(Supuestos!$F$28:$F$31,MATCH(G12,Supuestos!$A$28:$A$31,0)) -> 6.4 | L12: =J12*INDEX(Supuestos!$G$28:$G$31,MATCH(G12,Supuestos!$A$28:$A$31,0)) -> 5.6 | M12: =J12*INDEX(Supuestos!$H$28:$H$31,MATCH(G12,Supuestos!$A$28:$A$31,0)) -> 4 | N12: =I12*Supuestos!$B$5 -> 0 | O12: =Supuestos!$B$18 -> 1 | P12: =J12+N12+O12 -> 17 | Q12: =K12*Supuestos!$B$36+L12*Supuestos!$B$39+M12*Supuestos!$B$40 -> 1280 | R12: =N12*Supuestos!$B$37 -> 0 | S12: =O12*Supuestos!$B$38 -> 80 | T12: =Q12+R12+S12 -> 1360 | U12: =INDEX(Supuestos!$E$28:$E$31,MATCH(G12,Supuestos!$A$28:$A$31,0)) -> 60 | V12: =(INDEX(Supuestos!$C$28:$C$31,MATCH(G12,Supuestos!$A$28:$A$31,0))*Supuestos!$B$13+INDEX(Supuestos!$D$28:$D$31,MATCH(G12,Supuestos!$A$28:$A$31,0))*Supuestos!$B$14)/1000000 -> 0.0005 | W12: =U12*Supuestos!$B$8*V12*Supuestos!$B$2 -> 0.2625 | X12: =U12*Supuestos!$B$8*(INDEX(Supuestos!$C$28:$C$31,MATCH(G12,Supuestos!$A$28:$A$31,0))*Supuestos!$B$22+INDEX(Supuestos!$D$28:$D$31,MATCH(G12,Supuestos!$A$28:$A$31,0))*Supuestos!$C$22)/1000000*Supuestos!$B$2 -> 2.625 | Y12: =Supuestos!$B$17*V12*Supuestos!$B$2 -> 0.875
A13: 9 | B13: Bloque 1 · GPIO | C13: Quién va primero | D13: Interrupciones | E13: Latencia, prioridades NVIC, BASEPRI vs PRIMASK, pin de traza | F13: Dos alarmas simultáneas | G13: L | H13: 2 | I13: 1 | J13: =INDEX(Supuestos!$B$28:$B$31,MATCH(G13,Supuestos!$A$28:$A$31,0)) -> 24 | K13: =J13*INDEX(Supuestos!$F$28:$F$31,MATCH(G13,Supuestos!$A$28:$A$31,0)) -> 10.8 | L13: =J13*INDEX(Supuestos!$G$28:$G$31,MATCH(G13,Supuestos!$A$28:$A$31,0)) -> 7.2 | M13: =J13*INDEX(Supuestos!$H$28:$H$31,MATCH(G13,Supuestos!$A$28:$A$31,0)) -> 6 | N13: =I13*Supuestos!$B$5 -> 6 | O13: =Supuestos!$B$18 -> 1 | P13: =J13+N13+O13 -> 31 | Q13: =K13*Supuestos!$B$36+L13*Supuestos!$B$39+M13*Supuestos!$B$40 -> 1920 | R13: =N13*Supuestos!$B$37 -> 480 | S13: =O13*Supuestos!$B$38 -> 80 | T13: =Q13+R13+S13 -> 2480 | U13: =INDEX(Supuestos!$E$28:$E$31,MATCH(G13,Supuestos!$A$28:$A$31,0)) -> 80 | V13: =(INDEX(Supuestos!$C$28:$C$31,MATCH(G13,Supuestos!$A$28:$A$31,0))*Supuestos!$B$13+INDEX(Supuestos!$D$28:$D$31,MATCH(G13,Supuestos!$A$28:$A$31,0))*Supuestos!$B$14)/1000000 -> 0.00065 | W13: =U13*Supuestos!$B$8*V13*Supuestos!$B$2 -> 0.455 | X13: =U13*Supuestos!$B$8*(INDEX(Supuestos!$C$28:$C$31,MATCH(G13,Supuestos!$A$28:$A$31,0))*Supuestos!$B$22+INDEX(Supuestos!$D$28:$D$31,MATCH(G13,Supuestos!$A$28:$A$31,0))*Supuestos!$C$22)/1000000*Supuestos!$B$2 -> 4.55 | Y13: =Supuestos!$B$17*V13*Supuestos!$B$2 -> 1.1375
A14: 10 | B14: Bloque 2 · Tiempo y serie | C14: Metrónomo de la banda | D14: Timers | E14: add_repeating_timer_ms; período vs frecuencia | F14: Banda con pulsos | G14: M | H14: 2 | I14: 0 | J14: =INDEX(Supuestos!$B$28:$B$31,MATCH(G14,Supuestos!$A$28:$A$31,0)) -> 16 | K14: =J14*INDEX(Supuestos!$F$28:$F$31,MATCH(G14,Supuestos!$A$28:$A$31,0)) -> 6.4 | L14: =J14*INDEX(Supuestos!$G$28:$G$31,MATCH(G14,Supuestos!$A$28:$A$31,0)) -> 5.6 | M14: =J14*INDEX(Supuestos!$H$28:$H$31,MATCH(G14,Supuestos!$A$28:$A$31,0)) -> 4 | N14: =I14*Supuestos!$B$5 -> 0 | O14: =Supuestos!$B$18 -> 1 | P14: =J14+N14+O14 -> 17 | Q14: =K14*Supuestos!$B$36+L14*Supuestos!$B$39+M14*Supuestos!$B$40 -> 1280 | R14: =N14*Supuestos!$B$37 -> 0 | S14: =O14*Supuestos!$B$38 -> 80 | T14: =Q14+R14+S14 -> 1360 | U14: =INDEX(Supuestos!$E$28:$E$31,MATCH(G14,Supuestos!$A$28:$A$31,0)) -> 60 | V14: =(INDEX(Supuestos!$C$28:$C$31,MATCH(G14,Supuestos!$A$28:$A$31,0))*Supuestos!$B$13+INDEX(Supuestos!$D$28:$D$31,MATCH(G14,Supuestos!$A$28:$A$31,0))*Supuestos!$B$14)/1000000 -> 0.0005 | W14: =U14*Supuestos!$B$8*V14*Supuestos!$B$2 -> 0.2625 | X14: =U14*Supuestos!$B$8*(INDEX(Supuestos!$C$28:$C$31,MATCH(G14,Supuestos!$A$28:$A$31,0))*Supuestos!$B$22+INDEX(Supuestos!$D$28:$D$31,MATCH(G14,Supuestos!$A$28:$A$31,0))*Supuestos!$C$22)/1000000*Supuestos!$B$2 -> 2.625 | Y14: =Supuestos!$B$17*V14*Supuestos!$B$2 -> 0.875
A15: 11 | B15: Bloque 2 · Tiempo y serie | C15: Sin deriva | D15: Timers | E15: Alarmas de hardware, deadlines acumulativos, jitter y drift | F15: Sincronía de dos máquinas | G15: L | H15: 2 | I15: 0 | J15: =INDEX(Supuestos!$B$28:$B$31,MATCH(G15,Supuestos!$A$28:$A$31,0)) -> 24 | K15: =J15*INDEX(Supuestos!$F$28:$F$31,MATCH(G15,Supuestos!$A$28:$A$31,0)) -> 10.8 | L15: =J15*INDEX(Supuestos!$G$28:$G$31,MATCH(G15,Supuestos!$A$28:$A$31,0)) -> 7.2 | M15: =J15*INDEX(Supuestos!$H$28:$H$31,MATCH(G15,Supuestos!$A$28:$A$31,0)) -> 6 | N15: =I15*Supuestos!$B$5 -> 0 | O15: =Supuestos!$B$18 -> 1 | P15: =J15+N15+O15 -> 25 | Q15: =K15*Supuestos!$B$36+L15*Supuestos!$B$39+M15*Supuestos!$B$40 -> 1920 | R15: =N15*Supuestos!$B$37 -> 0 | S15: =O15*Supuestos!$B$38 -> 80 | T15: =Q15+R15+S15 -> 2000 | U15: =INDEX(Supuestos!$E$28:$E$31,MATCH(G15,Supuestos!$A$28:$A$31,0)) -> 80 | V15: =(INDEX(Supuestos!$C$28:$C$31,MATCH(G15,Supuestos!$A$28:$A$31,0))*Supuestos!$B$13+INDEX(Supuestos!$D$28:$D$31,MATCH(G15,Supuestos!$A$28:$A$31,0))*Supuestos!$B$14)/1000000 -> 0.00065 | W15: =U15*Supuestos!$B$8*V15*Supuestos!$B$2 -> 0.455 | X15: =U15*Supuestos!$B$8*(INDEX(Supuestos!$C$28:$C$31,MATCH(G15,Supuestos!$A$28:$A$31,0))*Supuestos!$B$22+INDEX(Supuestos!$D$28:$D$31,MATCH(G15,Supuestos!$A$28:$A$31,0))*Supuestos!$C$22)/1000000*Supuestos!$B$2 -> 4.55 | Y15: =Supuestos!$B$17*V15*Supuestos!$B$2 -> 1.1375
A16: 12 | B16: Bloque 2 · Tiempo y serie | C16: Sin bloquear la línea | D16: Timers | E16: Timer en segundo plano mientras main() lee entradas | F16: Línea que sigue mientras se lee un botón | G16: M | H16: 2 | I16: 0 | J16: =INDEX(Supuestos!$B$28:$B$31,MATCH(G16,Supuestos!$A$28:$A$31,0)) -> 16 | K16: =J16*INDEX(Supuestos!$F$28:$F$31,MATCH(G16,Supuestos!$A$28:$A$31,0)) -> 6.4 | L16: =J16*INDEX(Supuestos!$G$28:$G$31,MATCH(G16,Supuestos!$A$28:$A$31,0)) -> 5.6 | M16: =J16*INDEX(Supuestos!$H$28:$H$31,MATCH(G16,Supuestos!$A$28:$A$31,0)) -> 4 | N16: =I16*Supuestos!$B$5 -> 0 | O16: =Supuestos!$B$18 -> 1 | P16: =J16+N16+O16 -> 17 | Q16: =K16*Supuestos!$B$36+L16*Supuestos!$B$39+M16*Supuestos!$B$40 -> 1280 | R16: =N16*Supuestos!$B$37 -> 0 | S16: =O16*Supuestos!$B$38 -> 80 | T16: =Q16+R16+S16 -> 1360 | U16: =INDEX(Supuestos!$E$28:$E$31,MATCH(G16,Supuestos!$A$28:$A$31,0)) -> 60 | V16: =(INDEX(Supuestos!$C$28:$C$31,MATCH(G16,Supuestos!$A$28:$A$31,0))*Supuestos!$B$13+INDEX(Supuestos!$D$28:$D$31,MATCH(G16,Supuestos!$A$28:$A$31,0))*Supuestos!$B$14)/1000000 -> 0.0005 | W16: =U16*Supuestos!$B$8*V16*Supuestos!$B$2 -> 0.2625 | X16: =U16*Supuestos!$B$8*(INDEX(Supuestos!$C$28:$C$31,MATCH(G16,Supuestos!$A$28:$A$31,0))*Supuestos!$B$22+INDEX(Supuestos!$D$28:$D$31,MATCH(G16,Supuestos!$A$28:$A$31,0))*Supuestos!$C$22)/1000000*Supuestos!$B$2 -> 2.625 | Y16: =Supuestos!$B$17*V16*Supuestos!$B$2 -> 0.875
... A26: 22 | B26: Bloque 3 · Analógico y buses | C26: Pantalla de planta | D26: I2C | E26: Varios dispositivos, pull-ups, timeouts | F26: OLED + expansor GPIO | G26: M | H26: 2 | I26: 1 | J26: =INDEX(Supuestos!$B$28:$B$31,MATCH(G26,Supuestos!$A$28:$A$31,0)) -> 16 | K26: =J26*INDEX(Supuestos!$F$28:$F$31,MATCH(G26,Supuestos!$A$28:$A$31,0)) -> 6.4 | L26: =J26*INDEX(Supuestos!$G$28:$G$31,MATCH(G26,Supuestos!$A$28:$A$31,0)) -> 5.6 | M26: =J26*INDEX(Supuestos!$H$28:$H$31,MATCH(G26,Supuestos!$A$28:$A$31,0)) -> 4 | N26: =I26*Supuestos!$B$5 -> 6 | O26: =Supuestos!$B$18 -> 1 | P26: =J26+N26+O26 -> 23 | Q26: =K26*Supuestos!$B$36+L26*Supuestos!$B$39+M26*Supuestos!$B$40 -> 1280 | R26: =N26*Supuestos!$B$37 -> 480 | S26: =O26*Supuestos!$B$38 -> 80 | T26: =Q26+R26+S26 -> 1840 | U26: =INDEX(Supuestos!$E$28:$E$31,MATCH(G26,Supuestos!$A$28:$A$31,0)) -> 60 | V26: =(INDEX(Supuestos!$C$28:$C$31,MATCH(G26,Supuestos!$A$28:$A$31,0))*Supuestos!$B$13+INDEX(Supuestos!$D$28:$D$31,MATCH(G26,Supuestos!$A$28:$A$31,0))*Supuestos!$B$14)/1000000 -> 0.0005 | W26: =U26*Supuestos!$B$8*V26*Supuestos!$B$2 -> 0.2625 | X26: =U26*Supuestos!$B$8*(INDEX(Supuestos!$C$28:$C$31,MATCH(G26,Supuestos!$A$28:$A$31,0))*Supuestos!$B$22+INDEX(Supuestos!$D$28:$D$31,MATCH(G26,Supuestos!$A$28:$A$31,0))*Supuestos!$C$22)/1000000*Supuestos!$B$2 -> 2.625 | Y26: =Supuestos!$B$17*V26*Supuestos!$B$2 -> 0.875
C27: TOTAL (los 3 bloques) | I27: =SUM(I5:I26) -> 13 | J27: =SUM(J5:J26) -> 360 | K27: =SUM(K5:K26) -> 148.4 | L27: =SUM(L5:L26) -> 121.6 | M27: =SUM(M5:M26) -> 90 | N27: =SUM(N5:N26) -> 78 | O27: =SUM(O5:O26) -> 22 | P27: =SUM(P5:P26) -> 460 | ... U27: =SUM(U5:U26) -> 1340 | W27: =SUM(W5:W26) -> 6.2825 | X27: =SUM(X5:X26) -> 62.825 | Y27: =SUM(Y5:Y26) -> 20.0375

Sheet Motor y HAL
A1: Lo que se construye una sola vez: motor, arte, sonido, venta y simulación de cada periférico
A2: Horas por tipo de trabajo (azul). Estimaciones de Claude, no medidas. Cada periférico de los 3 bloques hay que simularlo dentro del juego antes de hacer niveles con él.
A4: Componente | B4: Tipo | C4: Parte del proyecto | D4: Escenario mínimo | E4: Prog. h | F4: Diseño gráfico h | G4: Sonido h | H4: Diseño de nivel y contenido h | I4: Pruebas y gestión h | J4: HORAS | K4: COSTO DIRECTO MXN | L4: Nota / riesgo
A5: Interfaz base en Godot (pantalla 60/40, editor, HUD, mini-trazas) | B5: Motor | C5: Motor del juego | D5: 1 | E5: 28 | F5: 8 | G5: 0 | H5: 2 | I5: 2 | J5: =SUM(E5:I5) -> 40 | K5: =E5*Supuestos!$B$36+F5*Supuestos!$B$37+G5*Supuestos!$B$38+H5*Supuestos!$B$39+I5*Supuestos!$B$40 -> 3200
A6: Cadena C++ → WASM (clang/wasi-sdk + WAMR + watchdog) | B6: Motor | C6: Motor del juego | D6: 1 | E6: 54 | F6: 0 | G6: 0 | H6: 0 | I6: 6 | J6: =SUM(E6:I6) -> 60 | K6: =E6*Supuestos!$B$36+F6*Supuestos!$B$37+G6*Supuestos!$B$38+H6*Supuestos!$B$39+I6*Supuestos!$B$40 -> 4800 | L6: El mayor riesgo técnico: nadie del equipo la ha hecho.
A7: Marco de niveles (JSON, validador, guardado) | B7: Motor | C7: Motor del juego | D7: 1 | E7: 24 | F7: 0 | G7: 0 | H7: 4 | I7: 2 | J7: =SUM(E7:I7) -> 30 | K7: =E7*Supuestos!$B$36+F7*Supuestos!$B$37+G7*Supuestos!$B$38+H7*Supuestos!$B$39+I7*Supuestos!$B$40 -> 2400
A8: Menú, primer arranque, cuenta Supabase y exportar portafolio | B8: Motor | C8: Motor del juego | D8: 1 | E8: 20 | F8: 6 | G8: 0 | H8: 2 | I8: 2 | J8: =SUM(E8:I8) -> 30 | K8: =E8*Supuestos!$B$36+F8*Supuestos!$B$37+G8*Supuestos!$B$38+H8*Supuestos!$B$39+I8*Supuestos!$B$40 -> 2400
A9: Migración del HAL de Arduino-ESP32 a Pico SDK (plantilla, etiquetas, documentos) | B9: Motor | C9: Motor del juego | D9: 1 | E9: 6 | F9: 0 | G9: 0 | H9: 4 | I9: 2 | J9: =SUM(E9:I9) -> 12 | K9: =E9*Supuestos!$B$36+F9*Supuestos!$B$37+G9*Supuestos!$B$38+H9*Supuestos!$B$39+I9*Supuestos!$B$40 -> 960 | L9: Solo si adoptan la API del curso.
A10: Copiloto IA (Edge Function, prompt escalonado, cuota, pistas locales) | B10: Motor | C10: Copiloto IA | D10: 1 | E10: 20 | F10: 0 | G10: 0 | H10: 8 | I10: 2 | J10: =SUM(E10:I10) -> 30 | K10: =E10*Supuestos!$B$36+F10*Supuestos!$B$37+G10*Supuestos!$B$38+H10*Supuestos!$B$39+I10*Supuestos!$B$40 -> 2400
A11: Arte base pixel (paleta, tiles, máquinas del nivel 1, retrato de la ingeniera) | B11: Arte | C11: Arte y animación base | D11: 1 | E11: 0 | F11: 30 | G11: 0 | H11: 0 | I11: 0 | J11: =SUM(E11:I11) -> 30 | K11: =E11*Supuestos!$B$36+F11*Supuestos!$B$37+G11*Supuestos!$B$38+H11*Supuestos!$B$39+I11*Supuestos!$B$40 -> 2400 | L11: Tope de 30 h de la decisión de la semana 6.
A12: Animaciones y efectos de la fábrica (chispas, luces cálidas, LEDs) | B12: Arte | C12: Arte y animación base | D12: 1 | E12: 4 | F12: 16 | G12: 0 | H12: 0 | I12: 0 | J12: =SUM(E12:I12) -> 20 | K12: =E12*Supuestos!$B$36+F12*Supuestos!$B$37+G12*Supuestos!$B$38+H12*Supuestos!$B$39+I12*Supuestos!$B$40 -> 1600 | L12: No estaba contado antes.
A13: Pulido de interfaz (iconos, estados de alerta, legibilidad en 1366×768) | B13: Arte | C13: Arte y animación base | D13: 1 | E13: 3 | F13: 10 | G13: 0 | H13: 0 | I13: 2 | J13: =SUM(E13:I13) -> 15 | K13: =E13*Supuestos!$B$36+F13*Supuestos!$B$37+G13*Supuestos!$B$38+H13*Supuestos!$B$39+I13*Supuestos!$B$40 -> 1200 | L13: No estaba contado antes.
A14: Sonido base (confirmaciones, alarmas, música; assets CC0) | B14: Sonido | C14: Sonido | D14: 1 | E14: 2 | F14: 0 | G14: 13 | H14: 0 | I14: 0 | J14: =SUM(E14:I14) -> 15 | K14: =E14*Supuestos!$B$36+F14*Supuestos!$B$37+G14*Supuestos!$B$38+H14*Supuestos!$B$39+I14*Supuestos!$B$40 -> 1200 | L14: No estaba contado antes.
A15: Página de venta, instalador y compilación | B15: Venta | C15: Venta y lanzamiento | D15: 1 | E15: 14 | F15: 0 | G15: 0 | H15: 4 | I15: 2 | J15: =SUM(E15:I15) -> 20 | K15: =E15*Supuestos!$B$36+F15*Supuestos!$B$37+G15*Supuestos!$B$38+H15*Supuestos!$B$39+I15*Supuestos!$B$40 -> 1600
A16: Arte de la página de venta (capturas, GIF, imagen principal) | B16: Venta | C16: Venta y lanzamiento | D16: 1 | E16: 0 | F16: 10 | G16: 0 | H16: 0 | I16: 0 | J16: =SUM(E16:I16) -> 10 | K16: =E16*Supuestos!$B$36+F16*Supuestos!$B$37+G16*Supuestos!$B$38+H16*Supuestos!$B$39+I16*Supuestos!$B$40 -> 800 | L16: No estaba contado antes.
A17: Piloto con 20 jugadores (preparar, dar soporte, analizar) | B17: Piloto | C17: Piloto | D17: 1 | E17: 4 | F17: 0 | G17: 0 | H17: 6 | I17: 10 | J17: =SUM(E17:I17) -> 20 | K17: =E17*Supuestos!$B$36+F17*Supuestos!$B$37+G17*Supuestos!$B$38+H17*Supuestos!$B$39+I17*Supuestos!$B$40 -> 1600
A18: GPIO / SIO y entradas con pull-ups | B18: Periférico | C18: Simulación de periféricos | D18: 1 | E18: 18 | F18: 0 | G18: 0 | H18: 0 | I18: 2 | J18: =SUM(E18:I18) -> 20 | K18: =E18*Supuestos!$B$36+F18*Supuestos!$B$37+G18*Supuestos!$B$38+H18*Supuestos!$B$39+I18*Supuestos!$B$40 -> 1600 | L18: Los registros se simulan en memoria lineal de WASM.
A19: Reloj, timers y alarmas (tiempo virtual) | B19: Periférico | C19: Simulación de periféricos | D19: 2 | E19: 22 | F19: 0 | G19: 0 | H19: 0 | I19: 3 | J19: =SUM(E19:I19) -> 25 | K19: =E19*Supuestos!$B$36+F19*Supuestos!$B$37+G19*Supuestos!$B$38+H19*Supuestos!$B$39+I19*Supuestos!$B$40 -> 2000
A20: Interrupciones de GPIO y NVIC con prioridades | B20: Periférico | C20: Simulación de periféricos | D20: 2 | E20: 27 | F20: 0 | G20: 0 | H20: 0 | I20: 3 | J20: =SUM(E20:I20) -> 30 | K20: =E20*Supuestos!$B$36+F20*Supuestos!$B$37+G20*Supuestos!$B$38+H20*Supuestos!$B$39+I20*Supuestos!$B$40 -> 2400 | L20: Simular latencia y apropiación exige tiempo virtual determinista.
A21: Analizador lógico / osciloscopio virtual | B21: Periférico | C21: Simulación de periféricos | D21: 2 | E21: 18 | F21: 5 | G21: 0 | H21: 0 | I21: 2 | J21: =SUM(E21:I21) -> 25 | K21: =E21*Supuestos!$B$36+F21*Supuestos!$B$37+G21*Supuestos!$B$38+H21*Supuestos!$B$39+I21*Supuestos!$B$40 -> 2000 | L21: El curso califica con mediciones de jitter y latencia.
A22: UART con FIFO y errores | B22: Periférico | C22: Simulación de periféricos | D22: 2 | E22: 22 | F22: 0 | G22: 0 | H22: 0 | I22: 3 | J22: =SUM(E22:I22) -> 25 | K22: =E22*Supuestos!$B$36+F22*Supuestos!$B$37+G22*Supuestos!$B$38+H22*Supuestos!$B$39+I22*Supuestos!$B$40 -> 2000
A23: PWM (slices, TOP, divisor) | B23: Periférico | C23: Simulación de periféricos | D23: 2 | E23: 13 | F23: 0 | G23: 0 | H23: 0 | I23: 2 | J23: =SUM(E23:I23) -> 15 | K23: =E23*Supuestos!$B$36+F23*Supuestos!$B$37+G23*Supuestos!$B$38+H23*Supuestos!$B$39+I23*Supuestos!$B$40 -> 1200
A24: ADC y señales analógicas (ruido, sensores) | B24: Periférico | C24: Simulación de periféricos | D24: 2 | E24: 12 | F24: 1 | G24: 0 | H24: 0 | I24: 2 | J24: =SUM(E24:I24) -> 15 | K24: =E24*Supuestos!$B$36+F24*Supuestos!$B$37+G24*Supuestos!$B$38+H24*Supuestos!$B$39+I24*Supuestos!$B$40 -> 1200
A25: I2C con dispositivos virtuales | B25: Periférico | C25: Simulación de periféricos | D25: 2 | E25: 22 | F25: 0 | G25: 0 | H25: 0 | I25: 3 | J25: =SUM(E25:I25) -> 25 | K25: =E25*Supuestos!$B$36+F25*Supuestos!$B$37+G25*Supuestos!$B$38+H25*Supuestos!$B$39+I25*Supuestos!$B$40 -> 2000
A26: TOTAL | E26: =SUM(E5:E25) -> 333 | F26: =SUM(F5:F25) -> 86 | G26: =SUM(G5:G25) -> 13 | H26: =SUM(H5:H25) -> 30 | I26: =SUM(I5:I25) -> 50 | J26: =SUM(J5:J25) -> 512 | K26: =SUM(K5:K25) -> 40960

Sheet Desglose
A1: Desglose: cuánto sale cada parte del proyecto y cada tipo de trabajo
A2: MVP = 5 niveles · 3 bloques = 22 niveles. 'Con ind. y cont.' = costo directo × (1 + indirectos) × (1 + contingencia).
A4: 1. Horas por tipo de trabajo
A5: Tipo de trabajo | B5: MVP | C5: 3 bloques
A6: Programación | B6: =SUMIFS('Motor y HAL'!$E$5:$E$25,'Motor y HAL'!$D$5:$D$25,"<=1")+SUMIFS(Niveles!$K$5:$K$26,Niveles!$H$5:$H$26,"<=1") -> 214.6 | C6: =SUMIFS('Motor y HAL'!$E$5:$E$25,'Motor y HAL'!$D$5:$D$25,"<=2")+SUMIFS(Niveles!$K$5:$K$26,Niveles!$H$5:$H$26,"<=2") -> 481.4
A7: Diseño gráfico | B7: =SUMIFS('Motor y HAL'!$F$5:$F$25,'Motor y HAL'!$D$5:$D$25,"<=1")+SUMIFS(Niveles!$N$5:$N$26,Niveles!$H$5:$H$26,"<=1") -> 98 | C7: =SUMIFS('Motor y HAL'!$F$5:$F$25,'Motor y HAL'!$D$5:$D$25,"<=2")+SUMIFS(Niveles!$N$5:$N$26,Niveles!$H$5:$H$26,"<=2") -> 164
A8: Sonido | B8: =SUMIFS('Motor y HAL'!$G$5:$G$25,'Motor y HAL'!$D$5:$D$25,"<=1")+SUMIFS(Niveles!$O$5:$O$26,Niveles!$H$5:$H$26,"<=1") -> 18 | C8: =SUMIFS('Motor y HAL'!$G$5:$G$25,'Motor y HAL'!$D$5:$D$25,"<=2")+SUMIFS(Niveles!$O$5:$O$26,Niveles!$H$5:$H$26,"<=2") -> 35
A9: Diseño de niveles y contenido | B9: =SUMIFS('Motor y HAL'!$H$5:$H$25,'Motor y HAL'!$D$5:$D$25,"<=1")+SUMIFS(Niveles!$L$5:$L$26,Niveles!$H$5:$H$26,"<=1") -> 48.4 | C9: =SUMIFS('Motor y HAL'!$H$5:$H$25,'Motor y HAL'!$D$5:$D$25,"<=2")+SUMIFS(Niveles!$L$5:$L$26,Niveles!$H$5:$H$26,"<=2") -> 151.6
A10: Pruebas y gestión | B10: =SUMIFS('Motor y HAL'!$I$5:$I$25,'Motor y HAL'!$D$5:$D$25,"<=1")+SUMIFS(Niveles!$M$5:$M$26,Niveles!$H$5:$H$26,"<=1") -> 44 | C10: =SUMIFS('Motor y HAL'!$I$5:$I$25,'Motor y HAL'!$D$5:$D$25,"<=2")+SUMIFS(Niveles!$M$5:$M$26,Niveles!$H$5:$H$26,"<=2") -> 140
A11: TOTAL DE HORAS | B11: =SUM(B6:B10) -> 423 | C11: =SUM(C6:C10) -> 972
A12: Gráfico + sonido como % del total | B12: =(B7+B8)/B11 -> 0.27423168 | C12: =(C7+C8)/C11 -> 0.20473251
A14: 2. Costo por tipo de trabajo (MXN)
A15: Tipo de trabajo | B15: MVP directo | C15: 3 bloques directo | D15: MVP con ind. y cont. | E15: 3 bloques con ind. y cont.
A16: Programación | B16: =B6*Supuestos!$B$36 -> 17168 | C16: =C6*Supuestos!$B$36 -> 38512 | D16: =B16*(1+Supuestos!$B$6)*(1+Supuestos!$B$7) -> 25666.16 | E16: =C16*(1+Supuestos!$B$6)*(1+Supuestos!$B$7) -> 57575.44
A17: Diseño gráfico | B17: =B7*Supuestos!$B$37 -> 7840 | C17: =C7*Supuestos!$B$37 -> 13120 | D17: =B17*(1+Supuestos!$B$6)*(1+Supuestos!$B$7) -> 11720.8 | E17: =C17*(1+Supuestos!$B$6)*(1+Supuestos!$B$7) -> 19614.4
A18: Sonido | B18: =B8*Supuestos!$B$38 -> 1440 | C18: =C8*Supuestos!$B$38 -> 2800 | D18: =B18*(1+Supuestos!$B$6)*(1+Supuestos!$B$7) -> 2152.8 | E18: =C18*(1+Supuestos!$B$6)*(1+Supuestos!$B$7) -> 4186
A19: Diseño de niveles y contenido | B19: =B9*Supuestos!$B$39 -> 3872 | C19: =C9*Supuestos!$B$39 -> 12128 | D19: =B19*(1+Supuestos!$B$6)*(1+Supuestos!$B$7) -> 5788.64 | E19: =C19*(1+Supuestos!$B$6)*(1+Supuestos!$B$7) -> 18131.36
A20: Pruebas y gestión | B20: =B10*Supuestos!$B$40 -> 3520 | C20: =C10*Supuestos!$B$40 -> 11200 | D20: =B20*(1+Supuestos!$B$6)*(1+Supuestos!$B$7) -> 5262.4 | E20: =C20*(1+Supuestos!$B$6)*(1+Supuestos!$B$7) -> 16744
A21: Subtotal de mano de obra (horas × tarifa) | B21: =SUM(B16:B20) -> 33840 | C21: =SUM(C16:C20) -> 77760 | D21: =SUM(D16:D20) -> 50590.8 | E21: =SUM(E16:E20) -> 116251.2
A22: Pruebas de IA durante el desarrollo (dinero real) | B22: =SUMIFS(Niveles!$Y$5:$Y$26,Niveles!$H$5:$H$26,"<=1") -> 3.85 | C22: =SUMIFS(Niveles!$Y$5:$Y$26,Niveles!$H$5:$H$26,"<=2") -> 20.0375 | D22: =B22*(1+Supuestos!$B$6)*(1+Supuestos!$B$7) -> 5.75575 | E22: =C22*(1+Supuestos!$B$6)*(1+Supuestos!$B$7) -> 29.956063
A23: TOTAL DE DESARROLLO | B23: =B21+B22 -> 33843.85 | C23: =C21+C22 -> 77780.038 | D23: =D21+D22 -> 50596.556 | E23: =E21+E22 -> 116281.16
A25: 3. Costo por parte del proyecto
A26: Parte del proyecto | B26: Horas MVP | C26: Horas 3 bloques | D26: MXN MVP (con ind. y cont.) | E26: MXN 3 bloques (con ind. y cont.) | F26: % del desarrollo (3 bloques) | G26: Qué incluye
A27: Motor del juego (interfaz, cadena WASM, marco de niveles, menú, migración) | B27: =SUMIFS('Motor y HAL'!$J$5:$J$25,'Motor y HAL'!$C$5:$C$25,"Motor del juego",'Motor y HAL'!$D$5:$D$25,"<=1") -> 172 | C27: =SUMIFS('Motor y HAL'!$J$5:$J$25,'Motor y HAL'!$C$5:$C$25,"Motor del juego",'Motor y HAL'!$D$5:$D$25,"<=2") -> 172 | D27: =(SUMIFS('Motor y HAL'!$K$5:$K$25,'Motor y HAL'!$C$5:$C$25,"Motor del juego",'Motor y HAL'!$D$5:$D$25,"<=1"))*(1+Supuestos!$B$6)*(1+Supuestos!$B$7) -> 20571.2 | E27: =(SUMIFS('Motor y HAL'!$K$5:$K$25,'Motor y HAL'!$C$5:$C$25,"Motor del juego",'Motor y HAL'!$D$5:$D$25,"<=2"))*(1+Supuestos!$B$6)*(1+Supuestos!$B$7) -> 20571.2 | F27: =E27/$E$39 -> 0.17690915 | G27: Programación del núcleo del juego.
A28: Copiloto IA (desarrollo) | B28: =SUMIFS('Motor y HAL'!$J$5:$J$25,'Motor y HAL'!$C$5:$C$25,"Copiloto IA",'Motor y HAL'!$D$5:$D$25,"<=1") -> 30 | C28: =SUMIFS('Motor y HAL'!$J$5:$J$25,'Motor y HAL'!$C$5:$C$25,"Copiloto IA",'Motor y HAL'!$D$5:$D$25,"<=2") -> 30 | D28: =(SUMIFS('Motor y HAL'!$K$5:$K$25,'Motor y HAL'!$C$5:$C$25,"Copiloto IA",'Motor y HAL'!$D$5:$D$25,"<=1"))*(1+Supuestos!$B$6)*(1+Supuestos!$B$7) -> 3588 | E28: =(SUMIFS('Motor y HAL'!$K$5:$K$25,'Motor y HAL'!$C$5:$C$25,"Copiloto IA",'Motor y HAL'!$D$5:$D$25,"<=2"))*(1+Supuestos!$B$6)*(1+Supuestos!$B$7) -> 3588 | F28: =E28/$E$39 -> 0.030856246 | G28: Edge Function, prompt escalonado, cuota.
A29: Simulación de los periféricos (GPIO, timers, interrupciones, UART, PWM, ADC, I2C) | B29: =SUMIFS('Motor y HAL'!$J$5:$J$25,'Motor y HAL'!$C$5:$C$25,"Simulación de periféricos",'Motor y HAL'!$D$5:$D$25,"<=1") -> 20 | C29: =SUMIFS('Motor y HAL'!$J$5:$J$25,'Motor y HAL'!$C$5:$C$25,"Simulación de periféricos",'Motor y HAL'!$D$5:$D$25,"<=2") -> 180 | D29: =(SUMIFS('Motor y HAL'!$K$5:$K$25,'Motor y HAL'!$C$5:$C$25,"Simulación de periféricos",'Motor y HAL'!$D$5:$D$25,"<=1"))*(1+Supuestos!$B$6)*(1+Supuestos!$B$7) -> 2392 | E29: =(SUMIFS('Motor y HAL'!$K$5:$K$25,'Motor y HAL'!$C$5:$C$25,"Simulación de periféricos",'Motor y HAL'!$D$5:$D$25,"<=2"))*(1+Supuestos!$B$6)*(1+Supuestos!$B$7) -> 21528 | F29: =E29/$E$39 -> 0.18513748 | G29: Lo que hace que el código del jugador mueva la fábrica.
A30: Arte y animación base | B30: =SUMIFS('Motor y HAL'!$J$5:$J$25,'Motor y HAL'!$C$5:$C$25,"Arte y animación base",'Motor y HAL'!$D$5:$D$25,"<=1") -> 65 | C30: =SUMIFS('Motor y HAL'!$J$5:$J$25,'Motor y HAL'!$C$5:$C$25,"Arte y animación base",'Motor y HAL'!$D$5:$D$25,"<=2") -> 65 | D30: =(SUMIFS('Motor y HAL'!$K$5:$K$25,'Motor y HAL'!$C$5:$C$25,"Arte y animación base",'Motor y HAL'!$D$5:$D$25,"<=1"))*(1+Supuestos!$B$6)*(1+Supuestos!$B$7) -> 7774 | E30: =(SUMIFS('Motor y HAL'!$K$5:$K$25,'Motor y HAL'!$C$5:$C$25,"Arte y animación base",'Motor y HAL'!$D$5:$D$25,"<=2"))*(1+Supuestos!$B$6)*(1+Supuestos!$B$7) -> 7774 | F30: =E30/$E$39 -> 0.0668552 | G30: Paleta, tiles, retrato, efectos y pulido de interfaz.
A31: Arte de las máquinas nuevas de los niveles | B31: =SUMIFS(Niveles!$N$5:$N$26,Niveles!$H$5:$H$26,"<=1") -> 18 | C31: =SUMIFS(Niveles!$N$5:$N$26,Niveles!$H$5:$H$26,"<=2") -> 78 | D31: =(SUMIFS(Niveles!$R$5:$R$26,Niveles!$H$5:$H$26,"<=1"))*(1+Supuestos!$B$6)*(1+Supuestos!$B$7) -> 2152.8 | E31: =(SUMIFS(Niveles!$R$5:$R$26,Niveles!$H$5:$H$26,"<=2"))*(1+Supuestos!$B$6)*(1+Supuestos!$B$7) -> 9328.8 | F31: =E31/$E$39 -> 0.080226241 | G31: Sprites y animación por máquina nueva.
A32: Sonido (base + por nivel) | B32: =SUMIFS('Motor y HAL'!$J$5:$J$25,'Motor y HAL'!$C$5:$C$25,"Sonido",'Motor y HAL'!$D$5:$D$25,"<=1")+SUMIFS(Niveles!$O$5:$O$26,Niveles!$H$5:$H$26,"<=1") -> 20 | C32: =SUMIFS('Motor y HAL'!$J$5:$J$25,'Motor y HAL'!$C$5:$C$25,"Sonido",'Motor y HAL'!$D$5:$D$25,"<=2")+SUMIFS(Niveles!$O$5:$O$26,Niveles!$H$5:$H$26,"<=2") -> 37 | D32: =(SUMIFS('Motor y HAL'!$K$5:$K$25,'Motor y HAL'!$C$5:$C$25,"Sonido",'Motor y HAL'!$D$5:$D$25,"<=1")+SUMIFS(Niveles!$S$5:$S$26,Niveles!$H$5:$H$26,"<=1"))*(1+Supuestos!$B$6)*(1+Supuestos!$B$7) -> 2392 | E32: =(SUMIFS('Motor y HAL'!$K$5:$K$25,'Motor y HAL'!$C$5:$C$25,"Sonido",'Motor y HAL'!$D$5:$D$25,"<=2")+SUMIFS(Niveles!$S$5:$S$26,Niveles!$H$5:$H$26,"<=2"))*(1+Supuestos!$B$6)*(1+Supuestos!$B$7) -> 4425.2 | F32: =E32/$E$39 -> 0.038056037 | G32: Efectos, alarmas y música.
A33: Niveles del Bloque 1 · GPIO (programación, diseño y pruebas) | B33: =SUMIFS(Niveles!$J$5:$J$26,Niveles!$B$5:$B$26,"Bloque 1 · GPIO",Niveles!$H$5:$H$26,"<=1") -> 48 | C33: =SUMIFS(Niveles!$J$5:$J$26,Niveles!$B$5:$B$26,"Bloque 1 · GPIO",Niveles!$H$5:$H$26,"<=2") -> 120 | D33: =(SUMIFS(Niveles!$Q$5:$Q$26,Niveles!$B$5:$B$26,"Bloque 1 · GPIO",Niveles!$H$5:$H$26,"<=1"))*(1+Supuestos!$B$6)*(1+Supuestos!$B$7) -> 5740.8 | E33: =(SUMIFS(Niveles!$Q$5:$Q$26,Niveles!$B$5:$B$26,"Bloque 1 · GPIO",Niveles!$H$5:$H$26,"<=2"))*(1+Supuestos!$B$6)*(1+Supuestos!$B$7) -> 14352 | F33: =E33/$E$39 -> 0.12342499 | G33: Niveles 1–9.
A34: Niveles del Bloque 2 · Tiempo y serie | B34: =SUMIFS(Niveles!$J$5:$J$26,Niveles!$B$5:$B$26,"Bloque 2 · Tiempo y serie",Niveles!$H$5:$H$26,"<=1") -> 0 | C34: =SUMIFS(Niveles!$J$5:$J$26,Niveles!$B$5:$B$26,"Bloque 2 · Tiempo y serie",Niveles!$H$5:$H$26,"<=2") -> 144 | D34: =(SUMIFS(Niveles!$Q$5:$Q$26,Niveles!$B$5:$B$26,"Bloque 2 · Tiempo y serie",Niveles!$H$5:$H$26,"<=1"))*(1+Supuestos!$B$6)*(1+Supuestos!$B$7) -> 0 | E34: =(SUMIFS(Niveles!$Q$5:$Q$26,Niveles!$B$5:$B$26,"Bloque 2 · Tiempo y serie",Niveles!$H$5:$H$26,"<=2"))*(1+Supuestos!$B$6)*(1+Supuestos!$B$7) -> 17222.4 | F34: =E34/$E$39 -> 0.14810998 | G34: Niveles 10–17.
A35: Niveles del Bloque 3 · Analógico y buses | B35: =SUMIFS(Niveles!$J$5:$J$26,Niveles!$B$5:$B$26,"Bloque 3 · Analógico y buses",Niveles!$H$5:$H$26,"<=1") -> 0 | C35: =SUMIFS(Niveles!$J$5:$J$26,Niveles!$B$5:$B$26,"Bloque 3 · Analógico y buses",Niveles!$H$5:$H$26,"<=2") -> 96 | D35: =(SUMIFS(Niveles!$Q$5:$Q$26,Niveles!$B$5:$B$26,"Bloque 3 · Analógico y buses",Niveles!$H$5:$H$26,"<=1"))*(1+Supuestos!$B$6)*(1+Supuestos!$B$7) -> 0 | E35: =(SUMIFS(Niveles!$Q$5:$Q$26,Niveles!$B$5:$B$26,"Bloque 3 · Analógico y buses",Niveles!$H$5:$H$26,"<=2"))*(1+Supuestos!$B$6)*(1+Supuestos!$B$7) -> 11481.6 | F35: =E35/$E$39 -> 0.098739988 | G35: Niveles 18–22.
A36: Página de venta, instalador y arte de venta | B36: =SUMIFS('Motor y HAL'!$J$5:$J$25,'Motor y HAL'!$C$5:$C$25,"Venta y lanzamiento",'Motor y HAL'!$D$5:$D$25,"<=1") -> 30 | C36: =SUMIFS('Motor y HAL'!$J$5:$J$25,'Motor y HAL'!$C$5:$C$25,"Venta y lanzamiento",'Motor y HAL'!$D$5:$D$25,"<=2") -> 30 | D36: =(SUMIFS('Motor y HAL'!$K$5:$K$25,'Motor y HAL'!$C$5:$C$25,"Venta y lanzamiento",'Motor y HAL'!$D$5:$D$25,"<=1"))*(1+Supuestos!$B$6)*(1+Supuestos!$B$7) -> 3588 | E36: =(SUMIFS('Motor y HAL'!$K$5:$K$25,'Motor y HAL'!$C$5:$C$25,"Venta y lanzamiento",'Motor y HAL'!$D$5:$D$25,"<=2"))*(1+Supuestos!$B$6)*(1+Supuestos!$B$7) -> 3588 | F36: =E36/$E$39 -> 0.030856246
A37: Piloto con 20 jugadores | B37: =SUMIFS('Motor y HAL'!$J$5:$J$25,'Motor y HAL'!$C$5:$C$25,"Piloto",'Motor y HAL'!$D$5:$D$25,"<=1") -> 20 | C37: =SUMIFS('Motor y HAL'!$J$5:$J$25,'Motor y HAL'!$C$5:$C$25,"Piloto",'Motor y HAL'!$D$5:$D$25,"<=2") -> 20 | D37: =(SUMIFS('Motor y HAL'!$K$5:$K$25,'Motor y HAL'!$C$5:$C$25,"Piloto",'Motor y HAL'!$D$5:$D$25,"<=1"))*(1+Supuestos!$B$6)*(1+Supuestos!$B$7) -> 2392 | E37: =(SUMIFS('Motor y HAL'!$K$5:$K$25,'Motor y HAL'!$C$5:$C$25,"Piloto",'Motor y HAL'!$D$5:$D$25,"<=2"))*(1+Supuestos!$B$6)*(1+Supuestos!$B$7) -> 2392 | F37: =E37/$E$39 -> 0.020570831
A38: Pruebas de IA durante el desarrollo (dinero real) | B38: 0 | C38: 0 | D38: =D22 -> 5.75575 | E38: =E22 -> 29.956063 | F38: =E38/$E$39 -> 0.00025761752
A39: TOTAL (debe coincidir con la sección 2) | B39: =SUM(B27:B38) -> 423 | C39: =SUM(C27:C38) -> 972 | D39: =SUM(D27:D38) -> 50596.556 | E39: =SUM(E27:E38) -> 116281.16 | F39: =SUM(F27:F38) -> 1
A40: Diferencia contra la sección 2 (debe ser 0) | D40: =ROUND(D39-D23,2) -> 0 | E40: =ROUND(E39-E23,2) -> 0
A42: 4. Costos fuera del desarrollo y total del proyecto (MXN)
A43: Concepto | B43: USD | C43: MXN | D43: Estado
A44: Cuota de Steam | B44: =Supuestos!B44 -> 100 | C44: =B44*Supuestos!$B$2 -> 1750 | D44: Verificado 9-oct-2026
...
